Workbook

Sheet Resumo IME
A2: Ano: 2023 | B2: Janeiro | C2: Fevereiro | D2: Março | E2: Abril | F2: Maio | G2: Junho | H2: Julho | I2: Agosto | J2: Setembro | K2: Outubro | L2: Novembro | M2: Dezembro
A3: Distribuição de subscritores por distrito | P3: Fevereiro | Q3: Março | R3: Abril | S3: Maio | T3: Junho | U3: Julho | V3: Agosto | W3: Setembro | X3: Outubro | Y3: Novembro | Z3: Dezembro
A4: Província de Maputo | B4: =SUM(B5:B14) -> 3477427 | C4: =SUM(C5:C14) -> 3578438 | D4: =SUM(D5:D14) -> 3661519 | E4: =SUM(E5:E14) -> 3723212 | F4: =SUM(F5:F14) -> 3765956 | G4: =SUM(G5:G14) -> 3809473 | H4: =SUM(H5:H14) -> 3816476 | I4: =SUM(I5:I14) -> 3854228 | ... M4: =SUM(M5:M14) -> 3930057 | P4: =+C4/B4-1 -> 0.029047626 | Q4: =+D5/C5-1 -> 0.03026853 | R4: =+E5/D5-1 -> -0.0084524642 | S4: =+F5/E5-1 -> 0.0079936434 | T4: =+G5/F5-1 -> 0.014520092 | U4: =+H5/G5-1 -> 0.0045907046 | V4: =+I5/H5-1 -> 0.027452133 | W4: =+J5/I5-1 -> -0.0025515521 | X4: =+K5/J5-1 -> 0.013382953 | ... Z4: =+M5/L5-1 -> -0.0007482929
A5: Cidade de Maputo | B5: =SUM('subscritores das IME 2023'!B7:J7) -> 1363586 | C5: =SUM('subscritores das IME 2023'!K7:S7) -> 1410607 | D5: =SUM('subscritores das IME 2023'!T7:AB7) -> 1453304 | E5: =SUM('subscritores das IME 2023'!AC7:AK7) -> 1441020 | F5: =SUM('subscritores das IME 2023'!AL7:AT7) -> 1452539 | G5: =SUM('subscritores das IME 2023'!AU7:BC7) -> 1473630 | H5: =SUM('subscritores das IME 2023'!BD7:BL7) -> 1480395 | I5: =SUM('subscritores das IME 2023'!BM7:BU7) -> 1521035 | J5: =SUM('subscritores das IME 2023'!BV7:CD7) -> 1517154 | K5: =SUM('subscritores das IME 2023'!CE7:CM7) -> 1537458 | L5: =SUM('subscritores das IME 2023'!CN7:CV7) -> 1556877 | M5: =SUM('subscritores das IME 2023'!CW7:DE7) -> 1555712 | P5: =+C5/B5-1 -> 0.03448334 | Q5: =+D5/C5-1 -> 0.03026853 | R5: =+E5/D5-1 -> -0.0084524642 | S5: =+F5/E5-1 -> 0.0079936434 | T5: =+G5/F5-1 -> 0.014520092 | U5: =+H5/G5-1 -> 0.0045907046 | V5: =+I5/H5-1 -> 0.027452133 | W5: =+J5/I5-1 -> -0.0025515521 | ... Z5: =+M5/L5-1 -> -0.0007482929
A6: Cidade da Matola | B6: =SUM('subscritores das IME 2023'!B8:J8) -> 1228654 | C6: =SUM('subscritores das IME 2023'!K8:S8) -> 1252772 | D6: =SUM('subscritores das IME 2023'!T8:AB8) -> 1272717 | E6: =SUM('subscritores das IME 2023'!AC8:AK8) -> 1295056 | F6: =SUM('subscritores das IME 2023'!AL8:AT8) -> 1304247 | G6: =SUM('subscritores das IME 2023'!AU8:BC8) -> 1317887 | H6: =SUM('subscritores das IME 2023'!BD8:BL8) -> 1321095 | I6: =SUM('subscritores das IME 2023'!BM8:BU8) -> 1318637 | J6: =SUM('subscritores das IME 2023'!BV8:CD8) -> 1324668 | K6: =SUM('subscritores das IME 2023'!CE8:CM8) -> 1338062 | L6: =SUM('subscritores das IME 2023'!CN8:CV8) -> 1341920 | M6: =SUM('subscritores das IME 2023'!CW8:DE8) -> 1356619 | P6: =+C6/B6-1 -> 0.019629611 | Q6: =+D6/C6-1 -> 0.015920694 | R6: =+E6/D6-1 -> 0.017552213 | S6: =+F6/E6-1 -> 0.0070969904 | T6: =+G6/F6-1 -> 0.010458142 | U6: =+H6/G6-1 -> 0.0024341996 | V6: =+I6/H6-1 -> -0.0018605778 | W6: =+J6/I6-1 -> 0.004573662 | ... Z6: =+M6/L6-1 -> 0.010953708
A7: Boane | B7: =SUM('subscritores das IME 2023'!B9:J9) -> 256903 | C7: =SUM('subscritores das IME 2023'!K9:S9) -> 262171 | D7: =SUM('subscritores das IME 2023'!T9:AB9) -> 266491 | E7: =SUM('subscritores das IME 2023'!AC9:AK9) -> 273243 | F7: =SUM('subscritores das IME 2023'!AL9:AT9) -> 273762 | G7: =SUM('subscritores das IME 2023'!AU9:BC9) -> 276373 | H7: =SUM('subscritores das IME 2023'!BD9:BL9) -> 278093 | I7: =SUM('subscritores das IME 2023'!BM9:BU9) -> 277472 | J7: =SUM('subscritores das IME 2023'!BV9:CD9) -> 280883 | K7: =SUM('subscritores das IME 2023'!CE9:CM9) -> 285055 | L7: =SUM('subscritores das IME 2023'!CN9:CV9) -> 283930 | M7: =SUM('subscritores das IME 2023'!CW9:DE9) -> 286627 | P7: =+C7/B7-1 -> 0.020505794 | Q7: =+D7/C7-1 -> 0.016477795 | R7: =+E7/D7-1 -> 0.025336691 | S7: =+F7/E7-1 -> 0.0018994082 | T7: =+G7/F7-1 -> 0.0095374815 | U7: =+H7/G7-1 -> 0.0062234733 | V7: =+I7/H7-1 -> -0.0022330659 | W7: =+J7/I7-1 -> 0.012293132 | ... Z7: =+M7/L7-1 -> 0.0094988201
A8: Magude | B8: =SUM('subscritores das IME 2023'!B10:J10) -> 32770 | C8: =SUM('subscritores das IME 2023'!K10:S10) -> 33488 | D8: =SUM('subscritores das IME 2023'!T10:AB10) -> 34766 | E8: =SUM('subscritores das IME 2023'!AC10:AK10) -> 35760 | F8: =SUM('subscritores das IME 2023'!AL10:AT10) -> 35505 | G8: =SUM('subscritores das IME 2023'!AU10:BC10) -> 36270 | H8: =SUM('subscritores das IME 2023'!BD10:BL10) -> 36162 | I8: =SUM('subscritores das IME 2023'!BM10:BU10) -> 35887 | J8: =SUM('subscritores das IME 2023'!BV10:CD10) -> 35734 | K8: =SUM('subscritores das IME 2023'!CE10:CM10) -> 36172 | L8: =SUM('subscritores das IME 2023'!CN10:CV10) -> 36276 | M8: =SUM('subscritores das IME 2023'!CW10:DE10) -> 36529 | P8: =+C8/B8-1 -> 0.021910284 | Q8: =+D8/C8-1 -> 0.038162924 | R8: =+E8/D8-1 -> 0.028591152 | S8: =+F8/E8-1 -> -0.0071308725 | T8: =+G8/F8-1 -> 0.021546261 | U8: =+H8/G8-1 -> -0.0029776675 | V8: =+I8/H8-1 -> -0.0076046679 | W8: =+J8/I8-1 -> -0.0042633823 | ... Z8: =+M8/L8-1 -> 0.0069743081
A9: Manhiça | B9: =SUM('subscritores das IME 2023'!B11:J11) -> 173512 | C9: =SUM('subscritores das IME 2023'!K11:S11) -> 177409 | D9: =SUM('subscritores das IME 2023'!T11:AB11) -> 178832 | E9: =SUM('subscritores das IME 2023'!AC11:AK11) -> 180214 | F9: =SUM('subscritores das IME 2023'!AL11:AT11) -> 179780 | G9: =SUM('subscritores das IME 2023'!AU11:BC11) -> 180395 | H9: =SUM('subscritores das IME 2023'!BD11:BL11) -> 179832 | I9: =SUM('subscritores das IME 2023'!BM11:BU11) -> 178375 | J9: =SUM('subscritores das IME 2023'!BV11:CD11) -> 175430 | K9: =SUM('subscritores das IME 2023'!CE11:CM11) -> 177907 | L9: =SUM('subscritores das IME 2023'!CN11:CV11) -> 176124 | M9: =SUM('subscritores das IME 2023'!CW11:DE11) -> 178591 | P9: =+C9/B9-1 -> 0.022459542 | Q9: =+D9/C9-1 -> 0.0080210136 | R9: =+E9/D9-1 -> 0.0077279234 | S9: =+F9/E9-1 -> -0.002408248 | T9: =+G9/F9-1 -> 0.0034208477 | U9: =+H9/G9-1 -> -0.0031209291 | V9: =+I9/H9-1 -> -0.0081020063 | W9: =+J9/I9-1 -> -0.016510161 | ... Z9: =+M9/L9-1 -> 0.014007177
A10: Marracuene | B10: =SUM('subscritores das IME 2023'!B12:J12) -> 236469 | C10: =SUM('subscritores das IME 2023'!K12:S12) -> 242454 | D10: =SUM('subscritores das IME 2023'!T12:AB12) -> 247345 | E10: =SUM('subscritores das IME 2023'!AC12:AK12) -> 285381 | F10: =SUM('subscritores das IME 2023'!AL12:AT12) -> 295087 | G10: =SUM('subscritores das IME 2023'!AU12:BC12) -> 297883 | H10: =SUM('subscritores das IME 2023'!BD12:BL12) -> 301702 | I10: =SUM('subscritores das IME 2023'!BM12:BU12) -> 303649 | J10: =SUM('subscritores das IME 2023'!BV12:CD12) -> 307326 | K10: =SUM('subscritores das IME 2023'!CE12:CM12) -> 310137 | L10: =SUM('subscritores das IME 2023'!CN12:CV12) -> 311744 | M10: =SUM('subscritores das IME 2023'!CW12:DE12) -> 317033 | P10: =+C10/B10-1 -> 0.025309871 | Q10: =+D10/C10-1 -> 0.020172899 | R10: =+E10/D10-1 -> 0.15377711 | S10: =+F10/E10-1 -> 0.034010673 | T10: =+G10/F10-1 -> 0.0094751717 | U10: =+H10/G10-1 -> 0.01282047 | V10: =+I10/H10-1 -> 0.0064533878 | W10: =+J10/I10-1 -> 0.012109376 | ... Z10: =+M10/L10-1 -> 0.016965844
A11: Matutuíne | B11: =SUM('subscritores das IME 2023'!B13:J13) -> 41106 | C11: =SUM('subscritores das IME 2023'!K13:S13) -> 43524 | D11: =SUM('subscritores das IME 2023'!T13:AB13) -> 45025 | E11: =SUM('subscritores das IME 2023'!AC13:AK13) -> 46367 | F11: =SUM('subscritores das IME 2023'!AL13:AT13) -> 47044 | G11: =SUM('subscritores das IME 2023'!AU13:BC13) -> 47098 | H11: =SUM('subscritores das IME 2023'!BD13:BL13) -> 46127 | I11: =SUM('subscritores das IME 2023'!BM13:BU13) -> 46670 | J11: =SUM('subscritores das IME 2023'!BV13:CD13) -> 46671 | K11: =SUM('subscritores das IME 2023'!CE13:CM13) -> 46632 | L11: =SUM('subscritores das IME 2023'!CN13:CV13) -> 47015 | M11: =SUM('subscritores das IME 2023'!CW13:DE13) -> 46447 | P11: =+C11/B11-1 -> 0.058823529 | Q11: =+D11/C11-1 -> 0.03448672 | R11: =+E11/D11-1 -> 0.029805664 | S11: =+F11/E11-1 -> 0.014600902 | T11: =+G11/F11-1 -> 0.0011478616 | U11: =+H11/G11-1 -> -0.020616587 | V11: =+I11/H11-1 -> 0.011771847 | W11: =+J11/I11-1 -> 2.1427041e-05 | ... Z11: =+M11/L11-1 -> -0.012081251
A12: Namaacha | B12: =SUM('subscritores das IME 2023'!B14:J14) -> 39367 | C12: =SUM('subscritores das IME 2023'!K14:S14) -> 40169 | D12: =SUM('subscritores das IME 2023'!T14:AB14) -> 42162 | E12: =SUM('subscritores das IME 2023'!AC14:AK14) -> 42038 | F12: =SUM('subscritores das IME 2023'!AL14:AT14) -> 46069 | G12: =SUM('subscritores das IME 2023'!AU14:BC14) -> 46993 | H12: =SUM('subscritores das IME 2023'!BD14:BL14) -> 44399 | I12: =SUM('subscritores das IME 2023'!BM14:BU14) -> 43927 | J12: =SUM('subscritores das IME 2023'!BV14:CD14) -> 43014 | K12: =SUM('subscritores das IME 2023'!CE14:CM14) -> 42180 | L12: =SUM('subscritores das IME 2023'!CN14:CV14) -> 41792 | M12: =SUM('subscritores das IME 2023'!CW14:DE14) -> 40434 | P12: =+C12/B12-1 -> 0.020372393 | Q12: =+D12/C12-1 -> 0.049615375 | R12: =+E12/D12-1 -> -0.002941037 | S12: =+F12/E12-1 -> 0.095889433 | T12: =+G12/F12-1 -> 0.020056871 | U12: =+H12/G12-1 -> -0.055199711 | V12: =+I12/H12-1 -> -0.01063087 | W12: =+J12/I12-1 -> -0.020784483 | ... Z12: =+M12/L12-1 -> -0.032494257
A13: Moamba | B13: =SUM('subscritores das IME 2023'!B15:J15) -> 105060 | C13: =SUM('subscritores das IME 2023'!K15:S15) -> 115844 | D13: =SUM('subscritores das IME 2023'!T15:AB15) -> 120877 | E13: =SUM('subscritores das IME 2023'!AC15:AK15) -> 124133 | F13: =SUM('subscritores das IME 2023'!AL15:AT15) -> 131923 | G13: =SUM('subscritores das IME 2023'!AU15:BC15) -> 132944 | H13: =SUM('subscritores das IME 2023'!BD15:BL15) -> 128671 | I13: =SUM('subscritores das IME 2023'!BM15:BU15) -> 128576 | J13: =SUM('subscritores das IME 2023'!BV15:CD15) -> 123577 | K13: =SUM('subscritores das IME 2023'!CE15:CM15) -> 124171 | L13: =SUM('subscritores das IME 2023'!CN15:CV15) -> 122879 | M13: =SUM('subscritores das IME 2023'!CW15:DE15) -> 112065 | P13: =+C13/B13-1 -> 0.10264611 | Q13: =+D13/C13-1 -> 0.043446359 | R13: =+E13/D13-1 -> 0.026936473 | S13: =+F13/E13-1 -> 0.062755271 | T13: =+G13/F13-1 -> 0.0077393631 | U13: =+H13/G13-1 -> -0.032141353 | V13: =+I13/H13-1 -> -0.0007383171 | W13: =+J13/I13-1 -> -0.038879729 | ... Z13: =+M13/L13-1 -> -0.088005273
B14: =SUM('subscritores das IME 2023'!B16:J16) -> 0 | C14: =SUM('subscritores das IME 2023'!K16:S16) -> 0 | D14: =SUM('subscritores das IME 2023'!T16:AB16) -> 0 | E14: =SUM('subscritores das IME 2023'!AC16:AK16) -> 0 | F14: =SUM('subscritores das IME 2023'!AL16:AT16) -> 0 | G14: =SUM('subscritores das IME 2023'!AU16:BC16) -> 0 | H14: =SUM('subscritores das IME 2023'!BD16:BL16) -> 0 | I14: =SUM('subscritores das IME 2023'!BM16:BU16) -> 0 | J14: =SUM('subscritores das IME 2023'!BV16:CD16) -> 0 | K14: =SUM('subscritores das IME 2023'!CE16:CM16) -> 0 | L14: =SUM('subscritores das IME 2023'!CN16:CV16) -> 0 | M14: =SUM('subscritores das IME 2023'!CW16:DE16) -> 0 | P14: =+C14/B14-1 -> #DIV/0! | Q14: =+D14/C14-1 -> #DIV/0! | R14: =+E14/D14-1 -> #DIV/0! | S14: =+F14/E14-1 -> #DIV/0! | T14: =+G14/F14-1 -> #DIV/0! | U14: =+H14/G14-1 -> #DIV/0! | V14: =+I14/H14-1 -> #DIV/0! | W14: =+J14/I14-1 -> #DIV/0! | ... Z14: =+M14/L14-1 -> #DIV/0!
A15: Gaza | B15: =SUM(B16:B30) -> 841021 | C15: =SUM(C16:C30) -> 833714 | D15: =SUM(D16:D30) -> 846011 | E15: =SUM(E16:E30) -> 858309 | F15: =SUM(F16:F30) -> 848957 | G15: =SUM(G16:G30) -> 856505 | H15: =SUM(H16:H30) -> 856572 | I15: =SUM(I16:I30) -> 860400 | ... M15: =SUM(M16:M30) -> 907842 | P15: =+C15/B15-1 -> -0.0086882492 | Q15: =+D15/C15-1 -> 0.014749662 | R15: =+E15/D15-1 -> 0.014536454 | S15: =+F15/E15-1 -> -0.010895843 | T15: =+G15/F15-1 -> 0.0088909097 | U15: =+H15/G15-1 -> 7.8224879e-05 | V15: =+I15/H15-1 -> 0.0044689763 | W15: =+J15/I15-1 -> 0.00023593677 | ... Z15: =+M15/L15-1 -> 0.041201122
A16: Cidade de Xai-Xai | B16: =SUM('subscritores das IME 2023'!B18:J18) -> 156596 | C16: =SUM('subscritores das IME 2023'!K18:S18) -> 158398 | D16: =SUM('subscritores das IME 2023'!T18:AB18) -> 159957 | E16: =SUM('subscritores das IME 2023'!AC18:AK18) -> 161836 | F16: =SUM('subscritores das IME 2023'!AL18:AT18) -> 161615 | G16: =SUM('subscritores das IME 2023'!AU18:BC18) -> 161498 | H16: =SUM('subscritores das IME 2023'!BD18:BL18) -> 161769 | I16: =SUM('subscritores das IME 2023'!BM18:BU18) -> 162670 | J16: =SUM('subscritores das IME 2023'!BV18:CD18) -> 163020 | K16: =SUM('subscritores das IME 2023'!CE18:CM18) -> 164059 | L16: =SUM('subscritores das IME 2023'!CN18:CV18) -> 163985 | M16: =SUM('subscritores das IME 2023'!CW18:DE18) -> 168020 | P16: =+C16/B16-1 -> 0.011507318 | Q16: =+D16/C16-1 -> 0.009842296 | R16: =+E16/D16-1 -> 0.011746907 | S16: =+F16/E16-1 -> -0.00136558 | T16: =+G16/F16-1 -> -0.0007239427 | U16: =+H16/G16-1 -> 0.0016780394 | V16: =+I16/H16-1 -> 0.0055696703 | W16: =+J16/I16-1 -> 0.0021515953 | ... Z16: =+M16/L16-1 -> 0.024605909
A17: Bilene-Macia | B17: =SUM('subscritores das IME 2023'!B19:J19) -> 133750 | C17: =SUM('subscritores das IME 2023'!K19:S19) -> 133057 | D17: =SUM('subscritores das IME 2023'!T19:AB19) -> 134229 | E17: =SUM('subscritores das IME 2023'!AC19:AK19) -> 135772 | F17: =SUM('subscritores das IME 2023'!AL19:AT19) -> 132401 | G17: =SUM('subscritores das IME 2023'!AU19:BC19) -> 134802 | H17: =SUM('subscritores das IME 2023'!BD19:BL19) -> 133935 | I17: =SUM('subscritores das IME 2023'!BM19:BU19) -> 134751 | J17: =SUM('subscritores das IME 2023'!BV19:CD19) -> 134667 | K17: =SUM('subscritores das IME 2023'!CE19:CM19) -> 135723 | L17: =SUM('subscritores das IME 2023'!CN19:CV19) -> 136430 | M17: =SUM('subscritores das IME 2023'!CW19:DE19) -> 143332 | P17: =+C17/B17-1 -> -0.0051813084 | Q17: =+D17/C17-1 -> 0.0088082551 | R17: =+E17/D17-1 -> 0.01149528 | S17: =+F17/E17-1 -> -0.024828389 | T17: =+G17/F17-1 -> 0.018134304 | U17: =+H17/G17-1 -> -0.0064316553 | V17: =+I17/H17-1 -> 0.0060925076 | W17: =+J17/I17-1 -> -0.000623372 | ... Z17: =+M17/L17-1 -> 0.050590046
A18: Chibuto | B18: =SUM('subscritores das IME 2023'!B20:J20) -> 109725 | C18: =SUM('subscritores das IME 2023'!K20:S20) -> 106966 | D18: =SUM('subscritores das IME 2023'!T20:AB20) -> 108578 | E18: =SUM('subscritores das IME 2023'!AC20:AK20) -> 109861 | F18: =SUM('subscritores das IME 2023'!AL20:AT20) -> 108732 | G18: =SUM('subscritores das IME 2023'!AU20:BC20) -> 109452 | H18: =SUM('subscritores das IME 2023'!BD20:BL20) -> 109400 | I18: =SUM('subscritores das IME 2023'!BM20:BU20) -> 110373 | J18: =SUM('subscritores das IME 2023'!BV20:CD20) -> 110972 | K18: =SUM('subscritores das IME 2023'!CE20:CM20) -> 112385 | L18: =SUM('subscritores das IME 2023'!CN20:CV20) -> 113383 | M18: =SUM('subscritores das IME 2023'!CW20:DE20) -> 118315 | P18: =+C18/B18-1 -> -0.02514468 | Q18: =+D18/C18-1 -> 0.015070209 | R18: =+E18/D18-1 -> 0.01181639 | S18: =+F18/E18-1 -> -0.010276622 | T18: =+G18/F18-1 -> 0.0066217857 | U18: =+H18/G18-1 -> -0.00047509411 | V18: =+I18/H18-1 -> 0.0088939671 | W18: =+J18/I18-1 -> 0.0054270519 | ... Z18: =+M18/L18-1 -> 0.043498584
A19: Chicualacuala | B19: =SUM('subscritores das IME 2023'!B21:J21) -> 8619 | C19: =SUM('subscritores das IME 2023'!K21:S21) -> 8460 | D19: =SUM('subscritores das IME 2023'!T21:AB21) -> 9072 | E19: =SUM('subscritores das IME 2023'!AC21:AK21) -> 9687 | F19: =SUM('subscritores das IME 2023'!AL21:AT21) -> 10764 | G19: =SUM('subscritores das IME 2023'!AU21:BC21) -> 11063 | H19: =SUM('subscritores das IME 2023'!BD21:BL21) -> 10971 | I19: =SUM('subscritores das IME 2023'!BM21:BU21) -> 11195 | J19: =SUM('subscritores das IME 2023'!BV21:CD21) -> 10957 | K19: =SUM('subscritores das IME 2023'!CE21:CM21) -> 11011 | L19: =SUM('subscritores das IME 2023'!CN21:CV21) -> 10855 | M19: =SUM('subscritores das IME 2023'!CW21:DE21) -> 10506 | P19: =+C19/B19-1 -> -0.018447616 | Q19: =+D19/C19-1 -> 0.072340426 | R19: =+E19/D19-1 -> 0.067791005 | S19: =+F19/E19-1 -> 0.11117993 | T19: =+G19/F19-1 -> 0.027777778 | U19: =+H19/G19-1 -> -0.0083160083 | V19: =+I19/H19-1 -> 0.020417464 | W19: =+J19/I19-1 -> -0.021259491 | ... Z19: =+M19/L19-1 -> -0.032151082
A20: Chigubo | B20: =SUM('subscritores das IME 2023'!B22:J22) -> 3999 | C20: =SUM('subscritores das IME 2023'!K22:S22) -> 4271 | D20: =SUM('subscritores das IME 2023'!T22:AB22) -> 4461 | E20: =SUM('subscritores das IME 2023'!AC22:AK22) -> 4658 | F20: =SUM('subscritores das IME 2023'!AL22:AT22) -> 4883 | G20: =SUM('subscritores das IME 2023'!AU22:BC22) -> 5101 | H20: =SUM('subscritores das IME 2023'!BD22:BL22) -> 5484 | I20: =SUM('subscritores das IME 2023'!BM22:BU22) -> 5747 | J20: =SUM('subscritores das IME 2023'!BV22:CD22) -> 5942 | K20: =SUM('subscritores das IME 2023'!CE22:CM22) -> 6147 | L20: =SUM('subscritores das IME 2023'!CN22:CV22) -> 6368 | M20: =SUM('subscritores das IME 2023'!CW22:DE22) -> 6214 | P20: =+C20/B20-1 -> 0.068017004 | Q20: =+D20/C20-1 -> 0.044486069 | R20: =+E20/D20-1 -> 0.044160502 | S20: =+F20/E20-1 -> 0.048303993 | T20: =+G20/F20-1 -> 0.044644686 | U20: =+H20/G20-1 -> 0.075083317 | V20: =+I20/H20-1 -> 0.047957695 | W20: =+J20/I20-1 -> 0.033930746 | ... Z20: =+M20/L20-1 -> -0.024183417
A21: Chókwè | B21: =SUM('subscritores das IME 2023'!B23:J23) -> 117401 | C21: =SUM('subscritores das IME 2023'!K23:S23) -> 117878 | D21: =SUM('subscritores das IME 2023'!T23:AB23) -> 120834 | E21: =SUM('subscritores das IME 2023'!AC23:AK23) -> 124188 | F21: =SUM('subscritores das IME 2023'!AL23:AT23) -> 122181 | G21: =SUM('subscritores das IME 2023'!AU23:BC23) -> 123536 | H21: =SUM('subscritores das IME 2023'!BD23:BL23) -> 124019 | I21: =SUM('subscritores das IME 2023'!BM23:BU23) -> 124979 | J21: =SUM('subscritores das IME 2023'!BV23:CD23) -> 123175 | K21: =SUM('subscritores das IME 2023'!CE23:CM23) -> 124287 | L21: =SUM('subscritores das IME 2023'!CN23:CV23) -> 124608 | M21: =SUM('subscritores das IME 2023'!CW23:DE23) -> 129322 | P21: =+C21/B21-1 -> 0.0040629978 | Q21: =+D21/C21-1 -> 0.025076774 | R21: =+E21/D21-1 -> 0.027757088 | S21: =+F21/E21-1 -> -0.016160982 | T21: =+G21/F21-1 -> 0.011090104 | U21: =+H21/G21-1 -> 0.0039097915 | V21: =+I21/H21-1 -> 0.0077407494 | W21: =+J21/I21-1 -> -0.014434425 | ... Z21: =+M21/L21-1 -> 0.037830637
A22: Guijá | B22: =SUM('subscritores das IME 2023'!B24:J24) -> 33514 | C22: =SUM('subscritores das IME 2023'!K24:S24) -> 33214 | D22: =SUM('subscritores das IME 2023'!T24:AB24) -> 33974 | E22: =SUM('subscritores das IME 2023'!AC24:AK24) -> 33840 | F22: =SUM('subscritores das IME 2023'!AL24:AT24) -> 34186 | G22: =SUM('subscritores das IME 2023'!AU24:BC24) -> 34734 | H22: =SUM('subscritores das IME 2023'!BD24:BL24) -> 35003 | I22: =SUM('subscritores das IME 2023'!BM24:BU24) -> 35134 | J22: =SUM('subscritores das IME 2023'!BV24:CD24) -> 35508 | K22: =SUM('subscritores das IME 2023'!CE24:CM24) -> 35919 | L22: =SUM('subscritores das IME 2023'!CN24:CV24) -> 36124 | M22: =SUM('subscritores das IME 2023'!CW24:DE24) -> 37386 | P22: =+C22/B22-1 -> -0.008951483 | Q22: =+D22/C22-1 -> 0.022881917 | R22: =+E22/D22-1 -> -0.0039441926 | S22: =+F22/E22-1 -> 0.010224586 | T22: =+G22/F22-1 -> 0.016029954 | U22: =+H22/G22-1 -> 0.007744573 | V22: =+I22/H22-1 -> 0.0037425364 | W22: =+J22/I22-1 -> 0.010644959 | ... Z22: =+M22/L22-1 -> 0.034935223
A23: Mabalane | B23: =SUM('subscritores das IME 2023'!B25:J25) -> 12121 | C23: =SUM('subscritores das IME 2023'!K25:S25) -> 12339 | D23: =SUM('subscritores das IME 2023'!T25:AB25) -> 12692 | E23: =SUM('subscritores das IME 2023'!AC25:AK25) -> 12728 | F23: =SUM('subscritores das IME 2023'!AL25:AT25) -> 12989 | G23: =SUM('subscritores das IME 2023'!AU25:BC25) -> 13045 | H23: =SUM('subscritores das IME 2023'!BD25:BL25) -> 13031 | I23: =SUM('subscritores das IME 2023'!BM25:BU25) -> 13401 | J23: =SUM('subscritores das IME 2023'!BV25:CD25) -> 13204 | K23: =SUM('subscritores das IME 2023'!CE25:CM25) -> 13532 | L23: =SUM('subscritores das IME 2023'!CN25:CV25) -> 13721 | M23: =SUM('subscritores das IME 2023'!CW25:DE25) -> 13723 | P23: =+C23/B23-1 -> 0.017985315 | Q23: =+D23/C23-1 -> 0.028608477 | R23: =+E23/D23-1 -> 0.0028364324 | S23: =+F23/E23-1 -> 0.020505971 | T23: =+G23/F23-1 -> 0.0043113404 | U23: =+H23/G23-1 -> -0.0010732081 | V23: =+I23/H23-1 -> 0.02839383 | W23: =+J23/I23-1 -> -0.014700395 | ... Z23: =+M23/L23-1 -> 0.00014576197
A24: Manjacaze | B24: =SUM('subscritores das IME 2023'!B26:J26) -> 84808 | C24: =SUM('subscritores das IME 2023'!K26:S26) -> 81901 | D24: =SUM('subscritores das IME 2023'!T26:AB26) -> 82800 | E24: =SUM('subscritores das IME 2023'!AC26:AK26) -> 84270 | F24: =SUM('subscritores das IME 2023'!AL26:AT26) -> 80441 | G24: =SUM('subscritores das IME 2023'!AU26:BC26) -> 80358 | H24: =SUM('subscritores das IME 2023'!BD26:BL26) -> 80839 | I24: =SUM('subscritores das IME 2023'!BM26:BU26) -> 80370 | J24: =SUM('subscritores das IME 2023'!BV26:CD26) -> 80513 | K24: =SUM('subscritores das IME 2023'!CE26:CM26) -> 82086 | L24: =SUM('subscritores das IME 2023'!CN26:CV26) -> 82677 | M24: =SUM('subscritores das IME 2023'!CW26:DE26) -> 87464 | P24: =+C24/B24-1 -> -0.034277427 | Q24: =+D24/C24-1 -> 0.010976667 | R24: =+E24/D24-1 -> 0.017753623 | S24: =+F24/E24-1 -> -0.045437285 | T24: =+G24/F24-1 -> -0.0010318121 | U24: =+H24/G24-1 -> 0.0059857139 | V24: =+I24/H24-1 -> -0.0058016551 | W24: =+J24/I24-1 -> 0.0017792709 | ... Z24: =+M24/L24-1 -> 0.057900021
A25: Massangena | B25: =SUM('subscritores das IME 2023'!B27:J27) -> 4284 | C25: =SUM('subscritores das IME 2023'!K27:S27) -> 4501 | D25: =SUM('subscritores das IME 2023'!T27:AB27) -> 4639 | E25: =SUM('subscritores das IME 2023'!AC27:AK27) -> 4788 | F25: =SUM('subscritores das IME 2023'!AL27:AT27) -> 4788 | G25: =SUM('subscritores das IME 2023'!AU27:BC27) -> 5051 | H25: =SUM('subscritores das IME 2023'!BD27:BL27) -> 5284 | I25: =SUM('subscritores das IME 2023'!BM27:BU27) -> 5395 | J25: =SUM('subscritores das IME 2023'!BV27:CD27) -> 5483 | K25: =SUM('subscritores das IME 2023'!CE27:CM27) -> 5577 | L25: =SUM('subscritores das IME 2023'!CN27:CV27) -> 5766 | M25: =SUM('subscritores das IME 2023'!CW27:DE27) -> 5887 | P25: =+C25/B25-1 -> 0.050653595 | Q25: =+D25/C25-1 -> 0.030659853 | R25: =+E25/D25-1 -> 0.032118991 | S25: =+F25/E25-1 -> 0 | T25: =+G25/F25-1 -> 0.054928989 | U25: =+H25/G25-1 -> 0.046129479 | V25: =+I25/H25-1 -> 0.021006813 | W25: =+J25/I25-1 -> 0.016311399 | ... Z25: =+M25/L25-1 -> 0.020985085
A26: Massingir | B26: =SUM('subscritores das IME 2023'!B28:J28) -> 8505 | C26: =SUM('subscritores das IME 2023'!K28:S28) -> 8827 | D26: =SUM('subscritores das IME 2023'!T28:AB28) -> 8918 | E26: =SUM('subscritores das IME 2023'!AC28:AK28) -> 8972 | F26: =SUM('subscritores das IME 2023'!AL28:AT28) -> 9294 | G26: =SUM('subscritores das IME 2023'!AU28:BC28) -> 9427 | H26: =SUM('subscritores das IME 2023'!BD28:BL28) -> 9790 | I26: =SUM('subscritores das IME 2023'!BM28:BU28) -> 10060 | J26: =SUM('subscritores das IME 2023'!BV28:CD28) -> 10347 | K26: =SUM('subscritores das IME 2023'!CE28:CM28) -> 10824 | L26: =SUM('subscritores das IME 2023'!CN28:CV28) -> 11010 | M26: =SUM('subscritores das IME 2023'!CW28:DE28) -> 11116 | P26: =+C26/B26-1 -> 0.037860082 | Q26: =+D26/C26-1 -> 0.010309278 | R26: =+E26/D26-1 -> 0.0060551693 | S26: =+F26/E26-1 -> 0.035889434 | T26: =+G26/F26-1 -> 0.014310308 | U26: =+H26/G26-1 -> 0.038506418 | V26: =+I26/H26-1 -> 0.027579162 | W26: =+J26/I26-1 -> 0.028528827 | ... Z26: =+M26/L26-1 -> 0.0096276113
A27: Chonguene | B27: =SUM('subscritores das IME 2023'!B29:J29) -> 75338 | C27: =SUM('subscritores das IME 2023'!K29:S29) -> 73709 | D27: =SUM('subscritores das IME 2023'!T29:AB29) -> 75057 | E27: =SUM('subscritores das IME 2023'!AC29:AK29) -> 75648 | F27: =SUM('subscritores das IME 2023'!AL29:AT29) -> 76062 | G27: =SUM('subscritores das IME 2023'!AU29:BC29) -> 76145 | H27: =SUM('subscritores das IME 2023'!BD29:BL29) -> 75045 | I27: =SUM('subscritores das IME 2023'!BM29:BU29) -> 74923 | J27: =SUM('subscritores das IME 2023'!BV29:CD29) -> 75231 | K27: =SUM('subscritores das IME 2023'!CE29:CM29) -> 75342 | L27: =SUM('subscritores das IME 2023'!CN29:CV29) -> 74966 | M27: =SUM('subscritores das IME 2023'!CW29:DE29) -> 78569 | P27: =+C27/B27-1 -> -0.021622554 | Q27: =+D27/C27-1 -> 0.018288133 | R27: =+E27/D27-1 -> 0.0078740157 | S27: =+F27/E27-1 -> 0.0054727157 | T27: =+G27/F27-1 -> 0.0010912151 | U27: =+H27/G27-1 -> -0.014446123 | V27: =+I27/H27-1 -> -0.0016256913 | W27: =+J27/I27-1 -> 0.0041108872 | ... Z27: =+M27/L27-1 -> 0.048061788
... A29: Limpopo | B29: =SUM('subscritores das IME 2023'!B31:J31) -> 81588 | C29: =SUM('subscritores das IME 2023'!K31:S31) -> 78896 | D29: =SUM('subscritores das IME 2023'!T31:AB31) -> 79005 | E29: =SUM('subscritores das IME 2023'!AC31:AK31) -> 79896 | F29: =SUM('subscritores das IME 2023'!AL31:AT31) -> 78103 | G29: =SUM('subscritores das IME 2023'!AU31:BC31) -> 79427 | H29: =SUM('subscritores das IME 2023'!BD31:BL31) -> 78788 | I29: =SUM('subscritores das IME 2023'!BM31:BU31) -> 77815 | J29: =SUM('subscritores das IME 2023'!BV31:CD31) -> 77775 | K29: =SUM('subscritores das IME 2023'!CE31:CM31) -> 77773 | L29: =SUM('subscritores das IME 2023'!CN31:CV31) -> 77593 | M29: =SUM('subscritores das IME 2023'!CW31:DE31) -> 83187 | P29: =+C29/B29-1 -> -0.032995048 | Q29: =+D29/C29-1 -> 0.0013815656 | R29: =+E29/D29-1 -> 0.011277767 | S29: =+F29/E29-1 -> -0.022441674 | T29: =+G29/F29-1 -> 0.016951974 | U29: =+H29/G29-1 -> -0.0080451232 | V29: =+I29/H29-1 -> -0.012349596 | W29: =+J29/I29-1 -> -0.00051403971 | ... Z29: =+M29/L29-1 -> 0.072094132
B30: =SUM('subscritores das IME 2023'!B32:J32) -> 0 | C30: =SUM('subscritores das IME 2023'!K32:S32) -> 0 | D30: =SUM('subscritores das IME 2023'!T32:AB32) -> 0 | E30: =SUM('subscritores das IME 2023'!AC32:AK32) -> 0 | F30: =SUM('subscritores das IME 2023'!AL32:AT32) -> 0 | G30: =SUM('subscritores das IME 2023'!AU32:BC32) -> 0 | H30: =SUM('subscritores das IME 2023'!BD32:BL32) -> 0 | I30: =SUM('subscritores das IME 2023'!BM32:BU32) -> 0 | J30: =SUM('subscritores das IME 2023'!BV32:CD32) -> 0 | K30: =SUM('subscritores das IME 2023'!CE32:CM32) -> 0 | L30: =SUM('subscritores das IME 2023'!CN32:CV32) -> 0 | M30: =SUM('subscritores das IME 2023'!CW32:DE32) -> 0 | P30: =+C30/B30-1 -> #DIV/0! | Q30: =+D30/C30-1 -> #DIV/0! | R30: =+E30/D30-1 -> #DIV/0! | S30: =+F30/E30-1 -> #DIV/0! | T30: =+G30/F30-1 -> #DIV/0! | U30: =+H30/G30-1 -> #DIV/0! | V30: =+I30/H30-1 -> #DIV/0! | W30: =+J30/I30-1 -> #DIV/0! | ... Z30: =+M30/L30-1 -> #DIV/0!
A31: Inhambane | B31: =SUM(B32:B46) -> 916998 | C31: =SUM(C32:C46) -> 902753 | D31: =SUM(D32:D46) -> 915078 | E31: =SUM(E32:E46) -> 926380 | F31: =SUM(F32:F46) -> 908764 | G31: =SUM(G32:G46) -> 918293 | H31: =SUM(H32:H46) -> 914299 | I31: =SUM(I32:I46) -> 916304 | ... M31: =SUM(M32:M46) -> 984381 | P31: =+C31/B31-1 -> -0.015534385 | Q31: =+D31/C31-1 -> 0.013652682 | R31: =+E31/D31-1 -> 0.01235086 | S31: =+F31/E31-1 -> -0.019015955 | T31: =+G31/F31-1 -> 0.010485671 | U31: =+H31/G31-1 -> -0.0043493743 | V31: =+I31/H31-1 -> 0.0021929369 | W31: =+J31/I31-1 -> 0.0041798355 | ... Z31: =+M31/L31-1 -> 0.043319142
A32: Cidade de Inhambane | B32: =SUM('subscritores das IME 2023'!B34:J34) -> 90707 | C32: =SUM('subscritores das IME 2023'!K34:S34) -> 91290 | D32: =SUM('subscritores das IME 2023'!T34:AB34) -> 93090 | E32: =SUM('subscritores das IME 2023'!AC34:AK34) -> 94986 | F32: =SUM('subscritores das IME 2023'!AL34:AT34) -> 97007 | G32: =SUM('subscritores das IME 2023'!AU34:BC34) -> 97848 | H32: =SUM('subscritores das IME 2023'!BD34:BL34) -> 96348 | I32: =SUM('subscritores das IME 2023'!BM34:BU34) -> 99250 | J32: =SUM('subscritores das IME 2023'!BV34:CD34) -> 100434 | K32: =SUM('subscritores das IME 2023'!CE34:CM34) -> 104011 | L32: =SUM('subscritores das IME 2023'!CN34:CV34) -> 105162 | M32: =SUM('subscritores das IME 2023'!CW34:DE34) -> 106902 | P32: =+C32/B32-1 -> 0.0064272879 | Q32: =+D32/C32-1 -> 0.019717384 | R32: =+E32/D32-1 -> 0.020367386 | S32: =+F32/E32-1 -> 0.02127682 | T32: =+G32/F32-1 -> 0.0086694775 | U32: =+H32/G32-1 -> -0.015329899 | V32: =+I32/H32-1 -> 0.030119982 | W32: =+J32/I32-1 -> 0.011929471 | ... Z32: =+M32/L32-1 -> 0.016545901
A33: Cidade de Maxixe | B33: =SUM('subscritores das IME 2023'!B35:J35) -> 124272 | C33: =SUM('subscritores das IME 2023'!K35:S35) -> 123065 | D33: =SUM('subscritores das IME 2023'!T35:AB35) -> 125788 | E33: =SUM('subscritores das IME 2023'!AC35:AK35) -> 127592 | F33: =SUM('subscritores das IME 2023'!AL35:AT35) -> 129282 | G33: =SUM('subscritores das IME 2023'!AU35:BC35) -> 129361 | H33: =SUM('subscritores das IME 2023'!BD35:BL35) -> 127782 | I33: =SUM('subscritores das IME 2023'!BM35:BU35) -> 127625 | J33: =SUM('subscritores das IME 2023'!BV35:CD35) -> 127473 | K33: =SUM('subscritores das IME 2023'!CE35:CM35) -> 128473 | L33: =SUM('subscritores das IME 2023'!CN35:CV35) -> 127803 | M33: =SUM('subscritores das IME 2023'!CW35:DE35) -> 131272 | P33: =+C33/B33-1 -> -0.009712566 | Q33: =+D33/C33-1 -> 0.022126519 | R33: =+E33/D33-1 -> 0.014341591 | S33: =+F33/E33-1 -> 0.013245345 | T33: =+G33/F33-1 -> 0.00061106728 | U33: =+H33/G33-1 -> -0.012206152 | V33: =+I33/H33-1 -> -0.0012286551 | W33: =+J33/I33-1 -> -0.0011909892 | ... Z33: =+M33/L33-1 -> 0.027143338
A34: Funhaloro | B34: =SUM('subscritores das IME 2023'!B36:J36) -> 12683 | C34: =SUM('subscritores das IME 2023'!K36:S36) -> 12648 | D34: =SUM('subscritores das IME 2023'!T36:AB36) -> 12813 | E34: =SUM('subscritores das IME 2023'!AC36:AK36) -> 13081 | F34: =SUM('subscritores das IME 2023'!AL36:AT36) -> 12937 | G34: =SUM('subscritores das IME 2023'!AU36:BC36) -> 13331 | H34: =SUM('subscritores das IME 2023'!BD36:BL36) -> 13359 | I34: =SUM('subscritores das IME 2023'!BM36:BU36) -> 13628 | J34: =SUM('subscritores das IME 2023'!BV36:CD36) -> 13854 | K34: =SUM('subscritores das IME 2023'!CE36:CM36) -> 14077 | L34: =SUM('subscritores das IME 2023'!CN36:CV36) -> 14357 | M34: =SUM('subscritores das IME 2023'!CW36:DE36) -> 15349 | P34: =+C34/B34-1 -> -0.0027595995 | Q34: =+D34/C34-1 -> 0.013045541 | R34: =+E34/D34-1 -> 0.020916257 | S34: =+F34/E34-1 -> -0.011008333 | T34: =+G34/F34-1 -> 0.030455283 | U34: =+H34/G34-1 -> 0.0021003676 | V34: =+I34/H34-1 -> 0.020136238 | W34: =+J34/I34-1 -> 0.016583505 | ... Z34: =+M34/L34-1 -> 0.069095215
A35: Govuro | B35: =SUM('subscritores das IME 2023'!B37:J37) -> 23554 | C35: =SUM('subscritores das IME 2023'!K37:S37) -> 23573 | D35: =SUM('subscritores das IME 2023'!T37:AB37) -> 24072 | E35: =SUM('subscritores das IME 2023'!AC37:AK37) -> 25067 | F35: =SUM('subscritores das IME 2023'!AL37:AT37) -> 24671 | G35: =SUM('subscritores das IME 2023'!AU37:BC37) -> 26560 | H35: =SUM('subscritores das IME 2023'!BD37:BL37) -> 26765 | I35: =SUM('subscritores das IME 2023'!BM37:BU37) -> 27358 | J35: =SUM('subscritores das IME 2023'!BV37:CD37) -> 27660 | K35: =SUM('subscritores das IME 2023'!CE37:CM37) -> 28594 | L35: =SUM('subscritores das IME 2023'!CN37:CV37) -> 29198 | M35: =SUM('subscritores das IME 2023'!CW37:DE37) -> 29310 | P35: =+C35/B35-1 -> 0.00080665704 | Q35: =+D35/C35-1 -> 0.021168286 | R35: =+E35/D35-1 -> 0.04133433 | S35: =+F35/E35-1 -> -0.015797662 | T35: =+G35/F35-1 -> 0.07656763 | U35: =+H35/G35-1 -> 0.0077183735 | V35: =+I35/H35-1 -> 0.0221558 | W35: =+J35/I35-1 -> 0.011038819 | ... Z35: =+M35/L35-1 -> 0.0038358792
A36: Homoine | B36: =SUM('subscritores das IME 2023'!B38:J38) -> 46109 | C36: =SUM('subscritores das IME 2023'!K38:S38) -> 45285 | D36: =SUM('subscritores das IME 2023'!T38:AB38) -> 46095 | E36: =SUM('subscritores das IME 2023'!AC38:AK38) -> 46257 | F36: =SUM('subscritores das IME 2023'!AL38:AT38) -> 45357 | G36: =SUM('subscritores das IME 2023'!AU38:BC38) -> 46392 | H36: =SUM('subscritores das IME 2023'!BD38:BL38) -> 46359 | I36: =SUM('subscritores das IME 2023'!BM38:BU38) -> 46727 | J36: =SUM('subscritores das IME 2023'!BV38:CD38) -> 46983 | K36: =SUM('subscritores das IME 2023'!CE38:CM38) -> 47735 | L36: =SUM('subscritores das IME 2023'!CN38:CV38) -> 47306 | M36: =SUM('subscritores das IME 2023'!CW38:DE38) -> 50576 | P36: =+C36/B36-1 -> -0.017870698 | Q36: =+D36/C36-1 -> 0.017886717 | R36: =+E36/D36-1 -> 0.003514481 | S36: =+F36/E36-1 -> -0.019456515 | T36: =+G36/F36-1 -> 0.02281897 | U36: =+H36/G36-1 -> -0.00071132954 | V36: =+I36/H36-1 -> 0.0079380487 | W36: =+J36/I36-1 -> 0.0054786312 | ... Z36: =+M36/L36-1 -> 0.069124424
A37: Inharrime | B37: =SUM('subscritores das IME 2023'!B39:J39) -> 70758 | C37: =SUM('subscritores das IME 2023'!K39:S39) -> 69845 | D37: =SUM('subscritores das IME 2023'!T39:AB39) -> 69784 | E37: =SUM('subscritores das IME 2023'!AC39:AK39) -> 68614 | F37: =SUM('subscritores das IME 2023'!AL39:AT39) -> 66435 | G37: =SUM('subscritores das IME 2023'!AU39:BC39) -> 66393 | H37: =SUM('subscritores das IME 2023'!BD39:BL39) -> 66867 | I37: =SUM('subscritores das IME 2023'!BM39:BU39) -> 66468 | J37: =SUM('subscritores das IME 2023'!BV39:CD39) -> 66183 | K37: =SUM('subscritores das IME 2023'!CE39:CM39) -> 66750 | L37: =SUM('subscritores das IME 2023'!CN39:CV39) -> 67648 | M37: =SUM('subscritores das IME 2023'!CW39:DE39) -> 72049 | P37: =+C37/B37-1 -> -0.012903135 | Q37: =+D37/C37-1 -> -0.00087336245 | R37: =+E37/D37-1 -> -0.016766021 | S37: =+F37/E37-1 -> -0.031757367 | T37: =+G37/F37-1 -> -0.00063219688 | U37: =+H37/G37-1 -> 0.0071393069 | V37: =+I37/H37-1 -> -0.005967069 | W37: =+J37/I37-1 -> -0.0042877776 | ... Z37: =+M37/L37-1 -> 0.065057356
A38: Inhassoro | B38: =SUM('subscritores das IME 2023'!B40:J40) -> 42405 | C38: =SUM('subscritores das IME 2023'!K40:S40) -> 43357 | D38: =SUM('subscritores das IME 2023'!T40:AB40) -> 44528 | E38: =SUM('subscritores das IME 2023'!AC40:AK40) -> 45734 | F38: =SUM('subscritores das IME 2023'!AL40:AT40) -> 45196 | G38: =SUM('subscritores das IME 2023'!AU40:BC40) -> 46128 | H38: =SUM('subscritores das IME 2023'!BD40:BL40) -> 46923 | I38: =SUM('subscritores das IME 2023'!BM40:BU40) -> 47413 | J38: =SUM('subscritores das IME 2023'!BV40:CD40) -> 47994 | K38: =SUM('subscritores das IME 2023'!CE40:CM40) -> 49235 | L38: =SUM('subscritores das IME 2023'!CN40:CV40) -> 49511 | M38: =SUM('subscritores das IME 2023'!CW40:DE40) -> 49081 | P38: =+C38/B38-1 -> 0.022450183 | Q38: =+D38/C38-1 -> 0.027008326 | R38: =+E38/D38-1 -> 0.027084082 | S38: =+F38/E38-1 -> -0.011763677 | T38: =+G38/F38-1 -> 0.020621294 | U38: =+H38/G38-1 -> 0.017234651 | V38: =+I38/H38-1 -> 0.01044264 | W38: =+J38/I38-1 -> 0.012254023 | ... Z38: =+M38/L38-1 -> -0.0086849387
A39: Jangamo | B39: =SUM('subscritores das IME 2023'!B41:J41) -> 65127 | C39: =SUM('subscritores das IME 2023'!K41:S41) -> 62139 | D39: =SUM('subscritores das IME 2023'!T41:AB41) -> 62012 | E39: =SUM('subscritores das IME 2023'!AC41:AK41) -> 62177 | F39: =SUM('subscritores das IME 2023'!AL41:AT41) -> 59087 | G39: =SUM('subscritores das IME 2023'!AU41:BC41) -> 59387 | H39: =SUM('subscritores das IME 2023'!BD41:BL41) -> 59447 | I39: =SUM('subscritores das IME 2023'!BM41:BU41) -> 58776 | J39: =SUM('subscritores das IME 2023'!BV41:CD41) -> 58984 | K39: =SUM('subscritores das IME 2023'!CE41:CM41) -> 59672 | L39: =SUM('subscritores das IME 2023'!CN41:CV41) -> 60115 | M39: =SUM('subscritores das IME 2023'!CW41:DE41) -> 64755 | P39: =+C39/B39-1 -> -0.045879589 | Q39: =+D39/C39-1 -> -0.002043805 | R39: =+E39/D39-1 -> 0.0026607753 | S39: =+F39/E39-1 -> -0.049696833 | T39: =+G39/F39-1 -> 0.005077259 | U39: =+H39/G39-1 -> 0.0010103221 | V39: =+I39/H39-1 -> -0.011287365 | W39: =+J39/I39-1 -> 0.0035388594 | ... Z39: =+M39/L39-1 -> 0.077185395
A40: Mabote | B40: =SUM('subscritores das IME 2023'!B42:J42) -> 14530 | C40: =SUM('subscritores das IME 2023'!K42:S42) -> 14881 | D40: =SUM('subscritores das IME 2023'!T42:AB42) -> 14802 | E40: =SUM('subscritores das IME 2023'!AC42:AK42) -> 15317 | F40: =SUM('subscritores das IME 2023'!AL42:AT42) -> 15388 | G40: =SUM('subscritores das IME 2023'!AU42:BC42) -> 15809 | H40: =SUM('subscritores das IME 2023'!BD42:BL42) -> 16314 | I40: =SUM('subscritores das IME 2023'!BM42:BU42) -> 16531 | J40: =SUM('subscritores das IME 2023'!BV42:CD42) -> 16945 | K40: =SUM('subscritores das IME 2023'!CE42:CM42) -> 17308 | L40: =SUM('subscritores das IME 2023'!CN42:CV42) -> 17736 | M40: =SUM('subscritores das IME 2023'!CW42:DE42) -> 18180 | P40: =+C40/B40-1 -> 0.024156917 | Q40: =+D40/C40-1 -> -0.005308783 | R40: =+E40/D40-1 -> 0.034792596 | S40: =+F40/E40-1 -> 0.0046353725 | T40: =+G40/F40-1 -> 0.027358981 | U40: =+H40/G40-1 -> 0.031943829 | V40: =+I40/H40-1 -> 0.013301459 | W40: =+J40/I40-1 -> 0.025043857 | ... Z40: =+M40/L40-1 -> 0.025033829
A41: Massinga | B41: =SUM('subscritores das IME 2023'!B43:J43) -> 136369 | C41: =SUM('subscritores das IME 2023'!K43:S43) -> 133446 | D41: =SUM('subscritores das IME 2023'!T43:AB43) -> 135545 | E41: =SUM('subscritores das IME 2023'!AC43:AK43) -> 136943 | F41: =SUM('subscritores das IME 2023'!AL43:AT43) -> 131617 | G41: =SUM('subscritores das IME 2023'!AU43:BC43) -> 132878 | H41: =SUM('subscritores das IME 2023'!BD43:BL43) -> 131872 | I41: =SUM('subscritores das IME 2023'!BM43:BU43) -> 130373 | J41: =SUM('subscritores das IME 2023'!BV43:CD43) -> 130477 | K41: =SUM('subscritores das IME 2023'!CE43:CM43) -> 132573 | L41: =SUM('subscritores das IME 2023'!CN43:CV43) -> 133856 | M41: =SUM('subscritores das IME 2023'!CW43:DE43) -> 140269 | P41: =+C41/B41-1 -> -0.02143449 | Q41: =+D41/C41-1 -> 0.015729209 | R41: =+E41/D41-1 -> 0.010313918 | S41: =+F41/E41-1 -> -0.038892094 | T41: =+G41/F41-1 -> 0.0095808292 | U41: =+H41/G41-1 -> -0.0075708545 | V41: =+I41/H41-1 -> -0.011367083 | W41: =+J41/I41-1 -> 0.00079771118 | ... Z41: =+M41/L41-1 -> 0.047909694
A42: Morrumbene | B42: =SUM('subscritores das IME 2023'!B44:J44) -> 63096 | C42: =SUM('subscritores das IME 2023'!K44:S44) -> 60400 | D42: =SUM('subscritores das IME 2023'!T44:AB44) -> 61033 | E42: =SUM('subscritores das IME 2023'!AC44:AK44) -> 61706 | F42: =SUM('subscritores das IME 2023'!AL44:AT44) -> 59037 | G42: =SUM('subscritores das IME 2023'!AU44:BC44) -> 59660 | H42: =SUM('subscritores das IME 2023'!BD44:BL44) -> 59284 | I42: =SUM('subscritores das IME 2023'!BM44:BU44) -> 58976 | J42: =SUM('subscritores das IME 2023'!BV44:CD44) -> 59269 | K42: =SUM('subscritores das IME 2023'!CE44:CM44) -> 59995 | L42: =SUM('subscritores das IME 2023'!CN44:CV44) -> 60476 | M42: =SUM('subscritores das IME 2023'!CW44:DE44) -> 64686 | P42: =+C42/B42-1 -> -0.042728541 | Q42: =+D42/C42-1 -> 0.010480132 | R42: =+E42/D42-1 -> 0.011026822 | S42: =+F42/E42-1 -> -0.043253492 | T42: =+G42/F42-1 -> 0.010552704 | U42: =+H42/G42-1 -> -0.0063023802 | V42: =+I42/H42-1 -> -0.0051953309 | W42: =+J42/I42-1 -> 0.0049681226 | ... Z42: =+M42/L42-1 -> 0.069614392
...

Sheet subscritores das IME 2023
A1: TABELA 11: Distribuição de clientes por distritos
A2: Ano: 2023
B3: Jan | K3: Fev | T3: Mar | AC3: Abril | AL3: Maio | AU3: Junho | BD3: Julho | BM3: Agosto | BV3: Setembro | CE3: Outubro | CN3: Novembro | CW3: Dezembro | DH3: Fev | DQ3: Mar | DZ3: Abril | EI3: Maio | ER3: Junho | FA3: Julho | FJ3: Agosto | FS3: Setembro | GB3: Outubro | GK3: Novembro | GT3: Dezembro
B4: Homens | F4: Mulheres | J4: Outros | K4: Homens | O4: Mulheres | S4: Outros | T4: Homens | X4: Mulheres | AB4: Outros | AC4: Homens | AG4: Mulheres | AK4: Outros | AL4: Homens | AP4: Mulheres | AT4: Outros | AU4: Homens | AY4: Mulheres | BC4: Outros | BD4: Homens | BH4: Mulheres | BL4: Outros | BM4: Homens | BQ4: Mulheres | BU4: Outros | BV4: Homens | BZ4: Mulheres | CD4: Outros | CE4: Homens | CI4: Mulheres | CM4: Outros | CN4: Homens | CR4: Mulheres | CV4: Outros | CW4: Homens | DA4: Mulheres | DE4: Outros | DH4: Homens | DL4: Mulheres | DP4: Outros | DQ4: Homens | DU4: Mulheres | DY4: Outros | DZ4: Homens | ED4: Mulheres | EH4: Outros | EI4: Homens | EM4: Mulheres | EQ4: Outros | ER4: Homens | EV4: Mulheres | EZ4: Outros | FA4: Homens | FE4: Mulheres | FI4: Outros | FJ4: Homens | FN4: Mulheres | FR4: Outros | FS4: Homens | FW4: Mulheres | GA4: Outros | GB4: Homens | GF4: Mulheres | GJ4: Outros | GK4: Homens | GO4: Mulheres | GS4: Outros | GT4: Homens | GX4: Mulheres | HB4: Outros
B5: 0 a 16 | C5: 17 a 21 | D5: 22 a 60 | E5: Mais de 60 | F5: 0 a 16 | G5: 17 a 21 | H5: 22 a 60 | I5: Mais de 60 | K5: 0 a 16 | L5: 17 a 21 | M5: 22 a 60 | N5: Mais de 60 | O5: 0 a 16 | P5: 17 a 21 | Q5: 22 a 60 | R5: Mais de 60 | T5: 0 a 16 | U5: 17 a 21 | V5: 22 a 60 | W5: Mais de 60 | X5: 0 a 16 | Y5: 17 a 21 | Z5: 22 a 60 | AA5: Mais de 60 | AC5: 0 a 16 | AD5: 17 a 21 | AE5: 22 a 60 | AF5: Mais de 60 | AG5: 0 a 16 | AH5: 17 a 21 | AI5: 22 a 60 | AJ5: Mais de 60 | AL5: 0 a 16 | AM5: 17 a 21 | AN5: 22 a 60 | AO5: Mais de 60 | AP5: 0 a 16 | AQ5: 17 a 21 | AR5: 22 a 60 | AS5: Mais de 60 | AU5: 0 a 16 | AV5: 17 a 21 | AW5: 22 a 60 | AX5: Mais de 60 | AY5: 0 a 16 | AZ5: 17 a 21 | BA5: 22 a 60 | BB5: Mais de 60 | BD5: 0 a 16 | BE5: 17 a 21 | BF5: 22 a 60 | BG5: Mais de 60 | BH5: 0 a 16 | BI5: 17 a 21 | BJ5: 22 a 60 | BK5: Mais de 60 | BM5: 0 a 16 | BN5: 17 a 21 | BO5: 22 a 60 | BP5: Mais de 60 | BQ5: 0 a 16 | BR5: 17 a 21 | BS5: 22 a 60 | BT5: Mais de 60 | BV5: 0 a 16 | BW5: 17 a 21 | BX5: 22 a 60 | BY5: Mais de 60 | BZ5: 0 a 16 | CA5: 17 a 21 | CB5: 22 a 60 | CC5: Mais de 60 | CE5: 0 a 16 | CF5: 17 a 21 | CG5: 22 a 60 | CH5: Mais de 60 | CI5: 0 a 16 | CJ5: 17 a 21 | CK5: 22 a 60 | CL5: Mais de 60 | CN5: 0 a 16 | CO5: 17 a 21 | CP5: 22 a 60 | CQ5: Mais de 60 | CR5: 0 a 16 | CS5: 17 a 21 | CT5: 22 a 60 | CU5: Mais de 60 | CW5: 0 a 16 | CX5: 17 a 21 | CY5: 22 a 60 | CZ5: Mais de 60 | DA5: 0 a 16 | DB5: 17 a 21 | DC5: 22 a 60 | DD5: Mais de 60 | DH5: 0 a 16 | DI5: 17 a 21 | DJ5: 22 a 60 | DK5: Mais de 60 | DL5: 0 a 16 | DM5: 17 a 21 | DN5: 22 a 60 | DO5: Mais de 60 | DQ5: 0 a 16 | DR5: 17 a 21 | DS5: 22 a 60 | DT5: Mais de 60 | DU5: 0 a 16 | DV5: 17 a 21 | DW5: 22 a 60 | DX5: Mais de 60 | DZ5: 0 a 16 | EA5: 17 a 21 | EB5: 22 a 60 | EC5: Mais de 60 | ED5: 0 a 16 | EE5: 17 a 21 | EF5: 22 a 60 | EG5: Mais de 60 | EI5: 0 a 16 | EJ5: 17 a 21 | EK5: 22 a 60 | EL5: Mais de 60 | EM5: 0 a 16 | EN5: 17 a 21 | EO5: 22 a 60 | EP5: Mais de 60 | ER5: 0 a 16 | ES5: 17 a 21 | ET5: 22 a 60 | EU5: Mais de 60 | EV5: 0 a 16 | EW5: 17 a 21 | EX5: 22 a 60 | EY5: Mais de 60 | FA5: 0 a 16 | FB5: 17 a 21 | FC5: 22 a 60 | FD5: Mais de 60 | FE5: 0 a 16 | FF5: 17 a 21 | FG5: 22 a 60 | FH5: Mais de 60 | FJ5: 0 a 16 | FK5: 17 a 21 | FL5: 22 a 60 | FM5: Mais de 60 | FN5: 0 a 16 | FO5: 17 a 21 | FP5: 22 a 60 | FQ5: Mais de 60 | FS5: 0 a 16 | FT5: 17 a 21 | FU5: 22 a 60 | FV5: Mais de 60 | FW5: 0 a 16 | FX5: 17 a 21 | FY5: 22 a 60 | FZ5: Mais de 60 | GB5: 0 a 16 | GC5: 17 a 21 | GD5: 22 a 60 | GE5: Mais de 60 | GF5: 0 a 16 | GG5: 17 a 21 | GH5: 22 a 60 | GI5: Mais de 60 | GK5: 0 a 16 | GL5: 17 a 21 | GM5: 22 a 60 | GN5: Mais de 60 | GO5: 0 a 16 | GP5: 17 a 21 | GQ5: 22 a 60 | GR5: Mais de 60 | GT5: 0 a 16 | GU5: 17 a 21 | GV5: 22 a 60 | GW5: Mais de 60 | GX5: 0 a 16 | GY5: 17 a 21 | GZ5: 22 a 60 | HA5: Mais de 60
A6: Província de Maputo | B6: =SUM(B7:B15) -> 247 | C6: =SUM(C7:C15) -> 177052 | D6: =SUM(D7:D15) -> 1497616 | E6: =SUM(E7:E15) -> 99177 | F6: =SUM(F7:F15) -> 283 | G6: =SUM(G7:G15) -> 177778 | H6: =SUM(H7:H15) -> 1376649 | I6: =SUM(I7:I15) -> 87936 | ... DE6: =SUM(DE7:DE15) -> 107804 | DH6: =+K6/B6-1 -> 0.064777328 | DI6: =+L6/C6-1 -> 0.04156406 | DJ6: =+M6/D6-1 -> 0.02707837 | DK6: =+N6/E6-1 -> 0.015850449 | DL6: =+O6/F6-1 -> 0.12014134 | DM6: =+P6/G6-1 -> 0.0399037 | DN6: =+Q6/H6-1 -> 0.026967658 | DO6: =+R6/I6-1 -> 0.036719887 | ... FU6: =+BX6/BO6-1 -> -0.0038768361
A7: Cidade de Maputo | B7: =+[3]Total!B7 -> 81 | C7: =+[3]Total!C7 -> 64666 | D7: =+[3]Total!D7 -> 575237 | E7: =+[3]Total!E7 -> 42305 | F7: =+[3]Total!F7 -> 96 | G7: =+[3]Total!G7 -> 69633 | H7: =+[3]Total!H7 -> 515706 | I7: =+[3]Total!I7 -> 37620 | ... DE7: =+[3]Total!DE7 -> 104995 | DH7: =+K7/B7-1 -> 0.037037037 | DI7: =+L7/C7-1 -> 0.046222126 | DJ7: =+M7/D7-1 -> 0.03160958 | DK7: =+N7/E7-1 -> 0.01961943 | DL7: =+O7/F7-1 -> 0.13541667 | DM7: =+P7/G7-1 -> 0.041445866 | DN7: =+Q7/H7-1 -> 0.032121015 | DO7: =+R7/I7-1 -> 0.042424242 | ... FU7: =+BX7/BO7-1 -> -0.012048677
A8: Cidade da Matola | B8: =+[3]Total!B8 -> 97 | C8: =+[3]Total!C8 -> 66954 | D8: =+[3]Total!D8 -> 522222 | E8: =+[3]Total!E8 -> 32698 | F8: =+[3]Total!F8 -> 122 | G8: =+[3]Total!G8 -> 66441 | H8: =+[3]Total!H8 -> 508614 | I8: =+[3]Total!I8 -> 29963 | ... DE8: =+[3]Total!DE8 -> 1842 | DH8: =+K8/B8-1 -> 0.092783505 | DI8: =+L8/C8-1 -> 0.028198465 | DJ8: =+M8/D8-1 -> 0.015893624 | DK8: =+N8/E8-1 -> 0.01156034 | DL8: =+O8/F8-1 -> 0.057377049 | DM8: =+P8/G8-1 -> 0.034406466 | DN8: =+Q8/H8-1 -> 0.020388743 | DO8: =+R8/I8-1 -> 0.027400461 | ... FU8: =+BX8/BO8-1 -> 0.0052699339
A9: Boane | B9: =+[3]Total!B9 -> 29 | C9: =+[3]Total!C9 -> 12420 | D9: =+[3]Total!D9 -> 117419 | E9: =+[3]Total!E9 -> 6916 | F9: =+[3]Total!F9 -> 30 | G9: =+[3]Total!G9 -> 11403 | H9: =+[3]Total!H9 -> 102913 | I9: =+[3]Total!I9 -> 5427 | ... DE9: =+[3]Total!DE9 -> 364 | DH9: =+K9/B9-1 -> -0.034482759 | DI9: =+L9/C9-1 -> 0.04742351 | DJ9: =+M9/D9-1 -> 0.018165714 | DK9: =+N9/E9-1 -> 0.0056390977 | DL9: =+O9/F9-1 -> 0.16666667 | DM9: =+P9/G9-1 -> 0.046391301 | DN9: =+Q9/H9-1 -> 0.017519653 | DO9: =+R9/I9-1 -> 0.030403538 | ... FU9: =+BX9/BO9-1 -> 0.012266757
A10: Magude | B10: =+[3]Total!B10 -> 3 | C10: =+[3]Total!C10 -> 1828 | D10: =+[3]Total!D10 -> 12544 | E10: =+[3]Total!E10 -> 1024 | F10: =+[3]Total!F10 -> 2 | G10: =+[3]Total!G10 -> 1898 | H10: =+[3]Total!H10 -> 14193 | I10: =+[3]Total!I10 -> 1254 | ... DE10: =+[3]Total!DE10 -> 22 | DH10: =+K10/B10-1 -> 0 | DI10: =+L10/C10-1 -> 0.055798687 | DJ10: =+M10/D10-1 -> 0.011957908 | DK10: =+N10/E10-1 -> 0 | DL10: =+O10/F10-1 -> 0 | DM10: =+P10/G10-1 -> 0.10590095 | DN10: =+Q10/H10-1 -> 0.017262031 | DO10: =+R10/I10-1 -> 0.016746411 | ... FU10: =+BX10/BO10-1 -> -0.013371963
A11: Manhiça | B11: =+[3]Total!B11 -> 15 | C11: =+[3]Total!C11 -> 9451 | D11: =+[3]Total!D11 -> 75508 | E11: =+[3]Total!E11 -> 5585 | F11: =+[3]Total!F11 -> 9 | G11: =+[3]Total!G11 -> 8553 | H11: =+[3]Total!H11 -> 69064 | I11: =+[3]Total!I11 -> 5150 | ... DE11: =+[3]Total!DE11 -> 159 | DH11: =+K11/B11-1 -> -0.066666667 | DI11: =+L11/C11-1 -> 0.051211512 | DJ11: =+M11/D11-1 -> 0.026129682 | DK11: =+N11/E11-1 -> 0.0041181737 | DL11: =+O11/F11-1 -> -0.22222222 | DM11: =+P11/G11-1 -> 0.023149772 | DN11: =+Q11/H11-1 -> 0.015217769 | DO11: =+R11/I11-1 -> 0.032815534 | ... FU11: =+BX11/BO11-1 -> -0.022426565
A12: Marracuene | B12: =+[3]Total!B12 -> 13 | C12: =+[3]Total!C12 -> 11920 | D12: =+[3]Total!D12 -> 106153 | E12: =+[3]Total!E12 -> 5303 | F12: =+[3]Total!F12 -> 19 | G12: =+[3]Total!G12 -> 11314 | H12: =+[3]Total!H12 -> 97162 | I12: =+[3]Total!I12 -> 4365 | ... DE12: =+[3]Total!DE12 -> 283 | DH12: =+K12/B12-1 -> 0.23076923 | DI12: =+L12/C12-1 -> 0.044966443 | DJ12: =+M12/D12-1 -> 0.020630599 | DK12: =+N12/E12-1 -> 0.011691495 | DL12: =+O12/F12-1 -> 0.21052632 | DM12: =+P12/G12-1 -> 0.04543044 | DN12: =+Q12/H12-1 -> 0.025668471 | DO12: =+R12/I12-1 -> 0.041695304 | ... FU12: =+BX12/BO12-1 -> 0.012993783
A13: Matutuíne | B13: =+[3]Total!B13 -> 1 | C13: =+[3]Total!C13 -> 2345 | D13: =+[3]Total!D13 -> 20050 | E13: =+[3]Total!E13 -> 1086 | F13: =+[3]Total!F13 -> 1 | G13: =+[3]Total!G13 -> 2095 | H13: =+[3]Total!H13 -> 14739 | I13: =+[3]Total!I13 -> 756 | ... DE13: =+[3]Total!DE13 -> 32 | DH13: =+K13/B13-1 -> -1 | DI13: =+L13/C13-1 -> 0.028997868 | DJ13: =+M13/D13-1 -> 0.061546135 | DK13: =+N13/E13-1 -> 0.043278085 | DL13: =+O13/F13-1 -> 1 | DM13: =+P13/G13-1 -> 0.044868735 | DN13: =+Q13/H13-1 -> 0.061740959 | DO13: =+R13/I13-1 -> 0.083333333 | ... FU13: =+BX13/BO13-1 -> -0.0049004321
A14: Namaacha | B14: =+[3]Total!B14 -> 3 | C14: =+[3]Total!C14 -> 2298 | D14: =+[3]Total!D14 -> 17791 | E14: =+[3]Total!E14 -> 1477 | F14: =+[3]Total!F14 -> 0 | G14: =+[3]Total!G14 -> 2020 | H14: =+[3]Total!H14 -> 14608 | I14: =+[3]Total!I14 -> 1136 | ... DE14: =+[3]Total!DE14 -> 26 | DH14: =+K14/B14-1 -> -0.33333333 | DI14: =+L14/C14-1 -> 0.048302872 | DJ14: =+M14/D14-1 -> 0.016581418 | DK14: =+N14/E14-1 -> -0.010832769 | DL14: =+O14/F14-1 -> #DIV/0! | DM14: =+P14/G14-1 -> 0.0074257426 | DN14: =+Q14/H14-1 -> 0.025944688 | DO14: =+R14/I14-1 -> 0.012323944 | ... FU14: =+BX14/BO14-1 -> -0.028226226
A15: Moamba | B15: =+[3]Total!B15 -> 5 | C15: =+[3]Total!C15 -> 5170 | D15: =+[3]Total!D15 -> 50692 | E15: =+[3]Total!E15 -> 2783 | F15: =+[3]Total!F15 -> 4 | G15: =+[3]Total!G15 -> 4421 | H15: =+[3]Total!H15 -> 39650 | I15: =+[3]Total!I15 -> 2265 | ... DE15: =+[3]Total!DE15 -> 81 | DH15: =+K15/B15-1 -> 1 | DI15: =+L15/C15-1 -> 0.11450677 | DJ15: =+M15/D15-1 -> 0.12023593 | DK15: =+N15/E15-1 -> 0.075098814 | DL15: =+O15/F15-1 -> 1 | DM15: =+P15/G15-1 -> 0.083917666 | DN15: =+Q15/H15-1 -> 0.083430013 | DO15: =+R15/I15-1 -> 0.087417219 | ... FU15: =+BX15/BO15-1 -> -0.039000452
B16: =+[3]Total!B16 -> 0 | C16: =+[3]Total!C16 -> 0 | D16: =+[3]Total!D16 -> 0 | E16: =+[3]Total!E16 -> 0 | F16: =+[3]Total!F16 -> 0 | G16: =+[3]Total!G16 -> 0 | H16: =+[3]Total!H16 -> 0 | I16: =+[3]Total!I16 -> 0 | ... DE16: =+[3]Total!DE16 -> 0 | DH16: =+K16/B16-1 -> #DIV/0! | DI16: =+L16/C16-1 -> #DIV/0! | DJ16: =+M16/D16-1 -> #DIV/0! | DK16: =+N16/E16-1 -> #DIV/0! | DL16: =+O16/F16-1 -> #DIV/0! | DM16: =+P16/G16-1 -> #DIV/0! | DN16: =+Q16/H16-1 -> #DIV/0! | DO16: =+R16/I16-1 -> #DIV/0! | ... FU16: =+BX16/BO16-1 -> #DIV/0!
A17: Gaza | B17: =SUM(B18:B31) -> 42 | C17: =SUM(C18:C31) -> 51470 | D17: =SUM(D18:D31) -> 310073 | E17: =SUM(E18:E31) -> 25210 | F17: =SUM(F18:F31) -> 53 | G17: =SUM(G18:G31) -> 59517 | H17: =SUM(H18:H31) -> 366073 | I17: =SUM(I18:I31) -> 28139 | ... DE17: =SUM(DE18:DE31) -> 342 | DH17: =+K17/B17-1 -> 0.52380952 | DI17: =+L17/C17-1 -> 0.0089955314 | DJ17: =+M17/D17-1 -> -0.017486205 | DK17: =+N17/E17-1 -> -0.0045220151 | DL17: =+O17/F17-1 -> 0.20754717 | DM17: =+P17/G17-1 -> 0.0022010518 | DN17: =+Q17/H17-1 -> -0.0085529389 | DO17: =+R17/I17-1 -> 0.026084793 | ... FU17: =+BX17/BO17-1 -> -0.0037742864
A18: Cidade de Xai-Xai | B18: =+[3]Total!B18 -> 8 | C18: =+[3]Total!C18 -> 10162 | D18: =+[3]Total!D18 -> 58922 | E18: =+[3]Total!E18 -> 4080 | F18: =+[3]Total!F18 -> 8 | G18: =+[3]Total!G18 -> 12019 | H18: =+[3]Total!H18 -> 67157 | I18: =+[3]Total!I18 -> 4124 | ... DE18: =+[3]Total!DE18 -> 93 | DH18: =+K18/B18-1 -> 0.5 | DI18: =+L18/C18-1 -> 0.029423342 | DJ18: =+M18/D18-1 -> 0.0061097722 | DK18: =+N18/E18-1 -> 0.021323529 | DL18: =+O18/F18-1 -> -0.25 | DM18: =+P18/G18-1 -> 0.021050004 | DN18: =+Q18/H18-1 -> 0.0093512218 | DO18: =+R18/I18-1 -> 0.040252182 | ... FU18: =+BX18/BO18-1 -> -0.0059900504
A19: Bilene-Macia | B19: =+[3]Total!B19 -> 11 | C19: =+[3]Total!C19 -> 8434 | D19: =+[3]Total!D19 -> 51731 | E19: =+[3]Total!E19 -> 3931 | F19: =+[3]Total!F19 -> 11 | G19: =+[3]Total!G19 -> 9035 | H19: =+[3]Total!H19 -> 56552 | I19: =+[3]Total!I19 -> 3987 | ... DE19: =+[3]Total!DE19 -> 52 | DH19: =+K19/B19-1 -> 0.63636364 | DI19: =+L19/C19-1 -> 0.014228124 | DJ19: =+M19/D19-1 -> -0.012526338 | DK19: =+N19/E19-1 -> 0.010684304 | DL19: =+O19/F19-1 -> 0.36363636 | DM19: =+P19/G19-1 -> -0.010957388 | DN19: =+Q19/H19-1 -> -0.0038725421 | DO19: =+R19/I19-1 -> 0.0248307 | ... FU19: =+BX19/BO19-1 -> -0.0059887533
A20: Chibuto | B20: =+[3]Total!B20 -> 4 | C20: =+[3]Total!C20 -> 6110 | D20: =+[3]Total!D20 -> 38701 | E20: =+[3]Total!E20 -> 3525 | F20: =+[3]Total!F20 -> 9 | G20: =+[3]Total!G20 -> 6879 | H20: =+[3]Total!H20 -> 49534 | I20: =+[3]Total!I20 -> 4870 | ... DE20: =+[3]Total!DE20 -> 74 | DH20: =+K20/B20-1 -> 1 | DI20: =+L20/C20-1 -> -0.017021277 | DJ20: =+M20/D20-1 -> -0.042582879 | DK20: =+N20/E20-1 -> -0.018439716 | DL20: =+O20/F20-1 -> -0.11111111 | DM20: =+P20/G20-1 -> 0.004215729 | DN20: =+Q20/H20-1 -> -0.02176283 | DO20: =+R20/I20-1 -> 0.020533881 | ... FU20: =+BX20/BO20-1 -> 0.0011810915
A21: Chicualacuala | B21: =+[3]Total!B21 -> 0 | C21: =+[3]Total!C21 -> 799 | D21: =+[3]Total!D21 -> 3154 | E21: =+[3]Total!E21 -> 194 | F21: =+[3]Total!F21 -> 0 | G21: =+[3]Total!G21 -> 1000 | H21: =+[3]Total!H21 -> 3312 | I21: =+[3]Total!I21 -> 159 | ... DE21: =+[3]Total!DE21 -> 0 | DH21: =+K21/B21-1 -> #DIV/0! | DI21: =+L21/C21-1 -> 0.025031289 | DJ21: =+M21/D21-1 -> -0.00063411541 | DK21: =+N21/E21-1 -> -0.10824742 | DL21: =+O21/F21-1 -> #DIV/0! | DM21: =+P21/G21-1 -> 0.024 | DN21: =+Q21/H21-1 -> -0.055857488 | DO21: =+R21/I21-1 -> 0.031446541 | ... FU21: =+BX21/BO21-1 -> -0.014753688
A22: Chigubo | B22: =+[3]Total!B22 -> 0 | C22: =+[3]Total!C22 -> 267 | D22: =+[3]Total!D22 -> 1709 | E22: =+[3]Total!E22 -> 106 | F22: =+[3]Total!F22 -> 0 | G22: =+[3]Total!G22 -> 296 | H22: =+[3]Total!H22 -> 1528 | I22: =+[3]Total!I22 -> 93 | ... DE22: =+[3]Total!DE22 -> 1 | DH22: =+K22/B22-1 -> #DIV/0! | DI22: =+L22/C22-1 -> 0.0037453184 | DJ22: =+M22/D22-1 -> 0.084844939 | DK22: =+N22/E22-1 -> 0 | DL22: =+O22/F22-1 -> #DIV/0! | DM22: =+P22/G22-1 -> 0.027027027 | DN22: =+Q22/H22-1 -> 0.066753927 | DO22: =+R22/I22-1 -> 0.17204301 | ... FU22: =+BX22/BO22-1 -> 0.033508276
A23: Chókwè | B23: =+[3]Total!B23 -> 6 | C23: =+[3]Total!C23 -> 6275 | D23: =+[3]Total!D23 -> 42497 | E23: =+[3]Total!E23 -> 3784 | F23: =+[3]Total!F23 -> 6 | G23: =+[3]Total!G23 -> 7522 | H23: =+[3]Total!H23 -> 52684 | I23: =+[3]Total!I23 -> 4575 | ... DE23: =+[3]Total!DE23 -> 40 | DH23: =+K23/B23-1 -> 0.33333333 | DI23: =+L23/C23-1 -> 0.018804781 | DJ23: =+M23/D23-1 -> -0.00063533897 | DK23: =+N23/E23-1 -> 0.013742072 | DL23: =+O23/F23-1 -> 0.5 | DM23: =+P23/G23-1 -> -0.0011964903 | DN23: =+Q23/H23-1 -> 0.0034545593 | DO23: =+R23/I23-1 -> 0.032568306 | ... FU23: =+BX23/BO23-1 -> -0.021499319
A24: Guijá | B24: =+[3]Total!B24 -> 1 | C24: =+[3]Total!C24 -> 1549 | D24: =+[3]Total!D24 -> 11819 | E24: =+[3]Total!E24 -> 1138 | F24: =+[3]Total!F24 -> 0 | G24: =+[3]Total!G24 -> 1985 | H24: =+[3]Total!H24 -> 15734 | I24: =+[3]Total!I24 -> 1267 | ... DE24: =+[3]Total!DE24 -> 10 | DH24: =+K24/B24-1 -> 0 | DI24: =+L24/C24-1 -> 0.018721756 | DJ24: =+M24/D24-1 -> -0.010237753 | DK24: =+N24/E24-1 -> -0.063268893 | DL24: =+O24/F24-1 -> #DIV/0! | DM24: =+P24/G24-1 -> -0.022166247 | DN24: =+Q24/H24-1 -> -0.0057836532 | DO24: =+R24/I24-1 -> 0.00078926598 | ... FU24: =+BX24/BO24-1 -> 0.013615862
A25: Mabalane | B25: =+[3]Total!B25 -> 0 | C25: =+[3]Total!C25 -> 739 | D25: =+[3]Total!D25 -> 5011 | E25: =+[3]Total!E25 -> 279 | F25: =+[3]Total!F25 -> 0 | G25: =+[3]Total!G25 -> 972 | H25: =+[3]Total!H25 -> 4774 | I25: =+[3]Total!I25 -> 344 | ... DE25: =+[3]Total!DE25 -> 1 | DH25: =+K25/B25-1 -> #DIV/0! | DI25: =+L25/C25-1 -> 0.0094722598 | DJ25: =+M25/D25-1 -> 0.032927559 | DK25: =+N25/E25-1 -> 0.043010753 | DL25: =+O25/F25-1 -> #DIV/0! | DM25: =+P25/G25-1 -> 0.0020576132 | DN25: =+Q25/H25-1 -> 0.0094260578 | DO25: =+R25/I25-1 -> -0.037790698 | ... FU25: =+BX25/BO25-1 -> -0.0085421412
A26: Manjacaze | B26: =+[3]Total!B26 -> 6 | C26: =+[3]Total!C26 -> 5772 | D26: =+[3]Total!D26 -> 30992 | E26: =+[3]Total!E26 -> 3056 | F26: =+[3]Total!F26 -> 5 | G26: =+[3]Total!G26 -> 6423 | H26: =+[3]Total!H26 -> 35247 | I26: =+[3]Total!I26 -> 3278 | ... DE26: =+[3]Total!DE26 -> 21 | DH26: =+K26/B26-1 -> 0.16666667 | DI26: =+L26/C26-1 -> -0.028413028 | DJ26: =+M26/D26-1 -> -0.045043882 | DK26: =+N26/E26-1 -> -0.027159686 | DL26: =+O26/F26-1 -> 0.6 | DM26: =+P26/G26-1 -> -0.031605169 | DN26: =+Q26/H26-1 -> -0.032258065 | DO26: =+R26/I26-1 -> 0.024100061 | ... FU26: =+BX26/BO26-1 -> 0.00014265335
A27: Massangena | B27: =+[3]Total!B27 -> 0 | C27: =+[3]Total!C27 -> 327 | D27: =+[3]Total!D27 -> 1733 | E27: =+[3]Total!E27 -> 119 | F27: =+[3]Total!F27 -> 0 | G27: =+[3]Total!G27 -> 407 | H27: =+[3]Total!H27 -> 1585 | I27: =+[3]Total!I27 -> 113 | ... DE27: =+[3]Total!DE27 -> 0 | DH27: =+K27/B27-1 -> #DIV/0! | DI27: =+L27/C27-1 -> 0.076452599 | DJ27: =+M27/D27-1 -> 0.041546451 | DK27: =+N27/E27-1 -> -0.084033613 | DL27: =+O27/F27-1 -> #DIV/0! | DM27: =+P27/G27-1 -> 0.029484029 | DN27: =+Q27/H27-1 -> 0.070031546 | DO27: =+R27/I27-1 -> 0.061946903 | ... FU27: =+BX27/BO27-1 -> 0.024118738
A28: Massingir | B28: =+[3]Total!B28 -> 0 | C28: =+[3]Total!C28 -> 667 | D28: =+[3]Total!D28 -> 3286 | E28: =+[3]Total!E28 -> 186 | F28: =+[3]Total!F28 -> 0 | G28: =+[3]Total!G28 -> 862 | H28: =+[3]Total!H28 -> 3371 | I28: =+[3]Total!I28 -> 132 | ... DE28: =+[3]Total!DE28 -> 1 | DH28: =+K28/B28-1 -> #DIV/0! | DI28: =+L28/C28-1 -> 0.0014992504 | DJ28: =+M28/D28-1 -> 0.059646987 | DK28: =+N28/E28-1 -> -0.0053763441 | DL28: =+O28/F28-1 -> #DIV/0! | DM28: =+P28/G28-1 -> 0.015081206 | DN28: =+Q28/H28-1 -> 0.028774844 | DO28: =+R28/I28-1 -> 0.12121212 | ... FU28: =+BX28/BO28-1 -> 0.032704068
A29: Chonguene | B29: =+[3]Total!B29 -> 3 | C29: =+[3]Total!C29 -> 4730 | D29: =+[3]Total!D29 -> 27227 | E29: =+[3]Total!E29 -> 2159 | F29: =+[3]Total!F29 -> 5 | G29: =+[3]Total!G29 -> 5621 | H29: =+[3]Total!H29 -> 33215 | I29: =+[3]Total!I29 -> 2338 | ... DE29: =+[3]Total!DE29 -> 24 | DH29: =+K29/B29-1 -> 0.33333333 | DI29: =+L29/C29-1 -> 0.013319239 | DJ29: =+M29/D29-1 -> -0.044992103 | DK29: =+N29/E29-1 -> -0.021769338 | DL29: =+O29/F29-1 -> 0.4 | DM29: =+P29/G29-1 -> 0.010496353 | DN29: =+Q29/H29-1 -> -0.016739425 | DO29: =+R29/I29-1 -> 0.034644996 | ... FU29: =+BX29/BO29-1 -> 0.00670347
... A31: Limpopo | B31: =+[3]Total!B31 -> 3 | C31: =+[3]Total!C31 -> 4678 | D31: =+[3]Total!D31 -> 29268 | E31: =+[3]Total!E31 -> 2373 | F31: =+[3]Total!F31 -> 9 | G31: =+[3]Total!G31 -> 5232 | H31: =+[3]Total!H31 -> 37388 | I31: =+[3]Total!I31 -> 2610 | ... DE31: =+[3]Total!DE31 -> 21 | DH31: =+K31/B31-1 -> 1 | DI31: =+L31/C31-1 -> -0.0017101325 | DJ31: =+M31/D31-1 -> -0.05265136 | DK31: =+N31/E31-1 -> -0.000842815 | DL31: =+O31/F31-1 -> 0.11111111 | DM31: =+P31/G31-1 -> 0.00095565749 | DN31: =+Q31/H31-1 -> -0.030758532 | DO31: =+R31/I31-1 -> 0.00076628352 | ... FU31: =+BX31/BO31-1 -> -0.0072343864
B32: =+[3]Total!B32 -> 0 | C32: =+[3]Total!C32 -> 0 | D32: =+[3]Total!D32 -> 0 | E32: =+[3]Total!E32 -> 0 | F32: =+[3]Total!F32 -> 0 | G32: =+[3]Total!G32 -> 0 | H32: =+[3]Total!H32 -> 0 | I32: =+[3]Total!I32 -> 0 | ... DE32: =+[3]Total!DE32 -> 0 | DH32: =+K32/B32-1 -> #DIV/0! | DI32: =+L32/C32-1 -> #DIV/0! | DJ32: =+M32/D32-1 -> #DIV/0! | DK32: =+N32/E32-1 -> #DIV/0! | DL32: =+O32/F32-1 -> #DIV/0! | DM32: =+P32/G32-1 -> #DIV/0! | DN32: =+Q32/H32-1 -> #DIV/0! | DO32: =+R32/I32-1 -> #DIV/0! | ... FU32: =+BX32/BO32-1 -> #DIV/0!
A33: Inhambane | B33: =SUM(B34:B47) -> 64 | C33: =SUM(C34:C47) -> 59444 | D33: =SUM(D34:D47) -> 367740 | E33: =SUM(E34:E47) -> 30765 | F33: =SUM(F34:F47) -> 59 | G33: =SUM(G34:G47) -> 61195 | H33: =SUM(H34:H47) -> 373135 | I33: =SUM(I34:I47) -> 24072 | ... DE33: =SUM(DE34:DE47) -> 447 | DH33: =+K33/B33-1 -> 0.09375 | DI33: =+L33/C33-1 -> -0.0033981562 | DJ33: =+M33/D33-1 -> -0.024435743 | DK33: =+N33/E33-1 -> -0.0082561352 | DL33: =+O33/F33-1 -> 0.25423729 | DM33: =+P33/G33-1 -> -0.0066181878 | DN33: =+Q33/H33-1 -> -0.013662615 | DO33: =+R33/I33-1 -> 0.028954802 | ... FU33: =+BX33/BO33-1 -> 0.0013127648
A34: Cidade de Inhambane | B34: =+[3]Total!B34 -> 4 | C34: =+[3]Total!C34 -> 6100 | D34: =+[3]Total!D34 -> 36544 | E34: =+[3]Total!E34 -> 2742 | F34: =+[3]Total!F34 -> 2 | G34: =+[3]Total!G34 -> 6438 | H34: =+[3]Total!H34 -> 36482 | I34: =+[3]Total!I34 -> 2269 | ... DE34: =+[3]Total!DE34 -> 123 | DH34: =+K34/B34-1 -> 0 | DI34: =+L34/C34-1 -> 0.034590164 | DJ34: =+M34/D34-1 -> -0.0033110771 | DK34: =+N34/E34-1 -> 0.0054704595 | DL34: =+O34/F34-1 -> 0.5 | DM34: =+P34/G34-1 -> 0.039763902 | DN34: =+Q34/H34-1 -> 0.0048242969 | DO34: =+R34/I34-1 -> 0.021595416 | ... FU34: =+BX34/BO34-1 -> 0.016444368
A35: Cidade de Maxixe | B35: =+[3]Total!B35 -> 7 | C35: =+[3]Total!C35 -> 8295 | D35: =+[3]Total!D35 -> 48227 | E35: =+[3]Total!E35 -> 3631 | F35: =+[3]Total!F35 -> 13 | G35: =+[3]Total!G35 -> 8907 | H35: =+[3]Total!H35 -> 51941 | I35: =+[3]Total!I35 -> 3184 | ... DE35: =+[3]Total!DE35 -> 61 | DH35: =+K35/B35-1 -> 0 | DI35: =+L35/C35-1 -> -0.011211573 | DJ35: =+M35/D35-1 -> -0.014493956 | DK35: =+N35/E35-1 -> -0.0038556871 | DL35: =+O35/F35-1 -> 0.15384615 | DM35: =+P35/G35-1 -> 0.0092062423 | DN35: =+Q35/H35-1 -> -0.01185961 | DO35: =+R35/I35-1 -> 0.039886935 | ... FU35: =+BX35/BO35-1 -> -0.0054904601
